<?xml version="1.0"?>
<robot name="hiroNx" xmlns:xacro="http://www.ros.org/wiki/xacro">

  <!-- Import all Gazebo-customization elements, including Gazebo colors -->
  <xacro:include filename="$(find hironx_description)/urdf/hiroNx.gazebo" />
  
  <!-- Import Rviz colors -->
  <xacro:include filename="$(find hironx_description)/urdf/materials.xacro" />

  <!-- Used for fixing robot to Gazebo 'base_link' -->
  <link name="world"/>
  
  <joint name="box" type="fixed">
    <parent link="world"/>
    <child link="BOX_LINK"/>
    <origin xyz="0 0 0.3" rpy="0 0 0"/>
  </joint>
  
  <link name="BOX_LINK">
	  <visual>
		  <origin xyz="0 0 0" rpy="0 0 0"/>
		  <geometry>
			  <box size="0.2 0.2 0.6"/>
		  </geometry>
		  <material name="black"/>
	  </visual>
	  
	  <!-- <collision>
		  <geometry>
			  <box size="0.2 0.2 0.6"/>
		  </geometry>
	  </collision> -->
	  
	  <interial>
		  <origin xyz="0 0 0.0" rpy="0 0 0"/> 
		  <mass value="20"/>
		  <!-- <inertia ixx="0.0101633" ixy="4.1629e-06" ixz="0.009100" iyy="0.0103116" iyz="-8.2277e-06" izz="0.801696"/> -->
		  <inertia
			ixx="8.3" ixy="0.0" ixz="0.0"
			iyy="8.3" iyz="0.0"
			izz="8.3"/> 
	  </interial> 
  </link>
  
  <!-- <joint name="kinect_joint" type="fixed">
    <origin xyz="0.05 0 0.08" rpy="0 0 0"/>
    <parent link="HEAD_JOINT1_Link"/>
    <child link="kinect_link"/>
  </joint> -->
  
  <!-- Kinect-->
  <!-- <link name="kinect_link"> -->
   <!-- <collision>
      <origin xyz="0 0 0" rpy="0 0 0"/>
      <geometry>
		<box size="0.1 0.2 0.05"/>
      </geometry>
    </collision> -->

  <!--  <visual>
      <origin xyz="0 0 0" rpy="0 0 0"/>
      <geometry>
		<box size="0.1 0.2 0.05"/>
      </geometry>
      <material name="red"/>
    </visual> -->

  <!--  <inertial>
      <mass value="0" />
      <origin xyz="0 0 0" rpy="0 0 0"/>
      <inertia ixx="1" ixy="0" ixz="0" iyy="1" iyz="0" izz="1" />
    </inertial> -->
  <!-- </link> -->
  
  <link name="WAIST">
    <visual>
      <origin xyz="0 0 0" rpy="0 0 0"/> 
      <geometry>
        <mesh filename="package://hironx_description/meshes/WAIST_mesh.dae" scale="1 1 1" />
      </geometry>
    </visual>
    
    <collision>
      <origin xyz="0 0 0" rpy="0 0 0"/>
      <geometry>
        <mesh filename="package://hironx_description/meshes/WAIST_mesh.dae" scale="1 1 1" />
      </geometry>
    </collision>
    
    <inertial>
      <mass value="2" />
      <origin xyz="0 0 0.12" rpy="0 -0 0"/>
      <inertia ixx="0.0127318" ixy="5.78001e-06" ixz="-3.34135e-05" iyy="0.0127482" iyz="6.35727e-07" izz="0.00438238"/>
    </inertial>
  </link>
  
  <joint name="fixed" type="fixed">
    <parent link="BOX_LINK"/>
    <child link="WAIST"/>
    <origin xyz="0 0 0.3" rpy="0 0 0"/>
  </joint>
  
  <link name="CHEST_JOINT0_Link">
    <visual>
      <origin xyz="0 0 0" rpy="0 -0 0"/>
      <geometry>
        <mesh filename="package://hironx_description/meshes/CHEST_JOINT0_Link_mesh.dae" scale="1 1 1" />
      </geometry>
      <material name="red"/>
    </visual>
    <collision>
      <origin xyz="0 0 0" rpy="0 -0 0"/>
      <geometry>
        <mesh filename="package://hironx_description/meshes/CHEST_JOINT0_Link_mesh.dae" scale="1 1 1" />
      </geometry>
    </collision>
    <inertial>
      <mass value="10" />
      <origin xyz="-0.041675 0 0.408175" rpy="0 -0 0"/>
      <inertia ixx="0.101633" ixy="4.1629e-06" ixz="0.009100" iyy="0.103116" iyz="-8.2277e-06" izz="0.0801696"/> 
      <!--<inertia ixx="0.0639575" ixy="-0.00022833" ixz="0.00011172" iyy="0.0310845" iyz="6.48e-05" izz="0.0501107"/>  -->
    </inertial>
  </link>
  
  <joint name="CHEST_JOINT0" type="revolute">
    <parent link="WAIST"/>
    <child  link="CHEST_JOINT0_Link"/>
    <origin xyz="0 0 0" rpy="0 -0 0 "/>
    <axis   xyz="0 0 1"/>
    <limit lower="-2.844" upper="2.844" effort="100" velocity="0.5" />
    <dynamics damping="0.5" friction="100.0" />
  </joint>
  
  <transmission name="CHEST_JOINT0_TRANS">
    <type>transmission_interface/SimpleTransmission</type>
    <joint name="CHEST_JOINT0">
      <hardwareInterface>EffortJointInterface</hardwareInterface>
    </joint>
    <actuator name="CHEST_JOINT0_MOTOR">
      <hardwareInterface>EffortJointInterface</hardwareInterface>
      <mechanicalReduction>1</mechanicalReduction>
    </actuator>
  </transmission>
  
  <link name="HEAD_JOINT0_Link">
    <visual>
      <origin xyz="0 0 0.5695" rpy="0 -0 0"/>
      <geometry>
        <mesh filename="package://hironx_description/meshes/HEAD_JOINT0_Link_mesh.dae" scale="1 1 1" />
      </geometry>
    </visual>
    
    <collision>
      <origin xyz="0 0 0.5695" rpy="0 -0 0"/>
      <geometry>
        <mesh filename="package://hironx_description/meshes/HEAD_JOINT0_Link_mesh.dae" scale="1 1 1" />
      </geometry>
    </collision>
    
    <inertial>
      <mass value="0.317929" />
      <origin xyz="-2.292e-05 0.00547848 -0.00784016" rpy="0 -0 0"/>
      <inertia ixx="0.00027682" ixy="3e-08" ixz="-3.3e-07" iyy="0.00013009" iyz="-1.092e-05" izz="0.00020954"/>
    </inertial>
  </link>
  
  <joint name="HEAD_JOINT0" type="revolute">
    <parent link="CHEST_JOINT0_Link"/>
    <child  link="HEAD_JOINT0_Link"/>
    <origin xyz="0 0 0.5695" rpy="0 -0 0 "/>
    <axis   xyz="0 0 1"/>
    <limit lower="-1.22173" upper="1.22173" effort="100" velocity="0.5" />
    <dynamics damping="0.4" friction="100.0" />
  </joint>
  
  <transmission name="HEAD_JOINT0_TRANS">
    <type>transmission_interface/SimpleTransmission</type>
    <joint name="HEAD_JOINT0">
      <hardwareInterface>EffortJointInterface</hardwareInterface>
    </joint>
    <actuator name="HEAD_JOINT0_MOTOR">
      <hardwareInterface>EffortJointInterface</hardwareInterface>
      <mechanicalReduction>1</mechanicalReduction>
    </actuator>
  </transmission>
  
  <link name="HEAD_JOINT1_Link">
    <visual>
      <origin xyz="0 0 0" rpy="0 -0 0"/>
      <geometry>
        <mesh filename="package://hironx_description/meshes/HEAD_JOINT1_Link_mesh.dae" scale="1 1 1" />
      </geometry>
      <material name="grey"/>
    </visual>
    
    <collision>
      <origin xyz="0 0 0" rpy="0 -0 0"/>
      <geometry>
        <mesh filename="package://hironx_description/meshes/HEAD_JOINT1_Link_mesh.dae" scale="1 1 1" />
      </geometry>
    </collision>
    
    <inertial>
      <mass value="0.0908593" />
      <origin xyz="-0.01444 0.000025 0.088" rpy="0 -0 0"/>
		<!-- <inertia ixx="8.07e-05" ixy="-3e-08" ixz="-4.30134e-22" iyy="3.025e-05" iyz="-1.277e-05" izz="6.637e-05"/> -->
        <inertia ixx="0.00045025254" ixy="-0.00000000308" ixz="0.00000011667" iyy="0.000502199" iyz="0.00000000297" izz="0.0008541012"/>
    </inertial>
  </link>
  
  <joint name="HEAD_JOINT1" type="revolute">
    <parent link="HEAD_JOINT0_Link"/>
    <child  link="HEAD_JOINT1_Link"/>
    <origin xyz="0 0 0" rpy="0 -0 0 "/>
    <axis   xyz="0 1 0"/>
    <limit lower="-0.349066" upper="1.22173" effort="100" velocity="0.5" />
    <dynamics damping="0.4" friction="100.0" />
  </joint>
  
  <transmission name="HEAD_JOINT1_TRANS">
    <type>transmission_interface/SimpleTransmission</type>
    <joint name="HEAD_JOINT1">
      <hardwareInterface>EffortJointInterface</hardwareInterface>
    </joint>
    <actuator name="HEAD_JOINT1_MOTOR">
      <hardwareInterface>EffortJointInterface</hardwareInterface>
      <mechanicalReduction>1</mechanicalReduction>
    </actuator>
  </transmission>
  
  <link name="LARM_JOINT0_Link">
    <visual>
      <origin xyz="0 0.145 0.370296" rpy="-0.261799 0 0"/>
      <geometry>
        <mesh filename="package://hironx_description/meshes/LARM_JOINT0_Link_mesh.dae" scale="1 1 1" />
      </geometry>
    </visual>
    
    <collision>
      <origin xyz="0 0.145 0.370296" rpy="-0.261799 0 0"/>
      <geometry>
        <mesh filename="package://hironx_description/meshes/LARM_JOINT0_Link_mesh.dae" scale="1 1 1" />
      </geometry>
    </collision>
    
    <inertial>
      <mass value="1.32626" />
      <origin xyz="-0.00226388 0.00521383 0.0176081" rpy="0 -0 0"/>
      <inertia ixx="0.00207537" ixy="0.00011276" ixz="8.927e-05" iyy="0.00240295" iyz="-4.57e-05" izz="0.00141912"/> 
      <!-- <origin xyz="-0.00226388 -0.00521383 0.0156081" rpy="0 -0 0"/> -->
    </inertial>
  </link>
  
  <joint name="LARM_JOINT0" type="revolute">
    <parent link="CHEST_JOINT0_Link"/>
    <child  link="LARM_JOINT0_Link"/>
    <origin xyz="0 0.145 0.370296" rpy="-0.261799 0 0 "/>
    <axis   xyz="0 0 1"/>
    <limit lower="-1.53589" upper="1.53589" effort="100" velocity="0.5" /> 
    <dynamics damping="0.4" friction="100.0" />
  </joint>
  
  <transmission name="LARM_JOINT0_TRANS">
    <type>transmission_interface/SimpleTransmission</type>
    <joint name="LARM_JOINT0">
      <hardwareInterface>EffortJointInterface</hardwareInterface>
    </joint>
    <actuator name="LARM_JOINT0_MOTOR">
      <hardwareInterface>EffortJointInterface</hardwareInterface>
      <mechanicalReduction>1</mechanicalReduction>
    </actuator>
  </transmission>
  
  <link name="LARM_JOINT1_Link">
    <visual>
      <origin xyz="0 0 0" rpy="0 -0 0"/>
      <geometry>
        <mesh filename="package://hironx_description/meshes/LARM_JOINT1_Link_mesh.dae" scale="1 1 1" />
      </geometry>
    </visual>
    
    <collision>
      <origin xyz="0 0 0" rpy="0 -0 0"/>
      <geometry>
        <mesh filename="package://hironx_description/meshes/LARM_JOINT1_Link_mesh.dae" scale="1 1 1" />
      </geometry>
    </collision>
    
    <inertial>
      <mass value="1.14898" />
      <origin xyz="-0.025 0.1083134 -0.127061" rpy="0 -0 0"/>
      <inertia ixx="0.0124168" ixy="-9.95417e-07" ixz="3.38147e-06" iyy="0.0127117" iyz="-0.00213719" izz="0.0013658"/>
      <!-- <origin xyz="-5.236e-05 0.0583134 -0.107061" rpy="0 -0 0"/> -->
      <!-- <inertia ixx="0.0154168" ixy="9.95417e-07" ixz="3.38147e-06" iyy="0.0147117" iyz="0.00213719" izz="0.0012658"/> -->
    </inertial>
  </link>
  
  <joint name="LARM_JOINT1" type="revolute">
    <parent link="LARM_JOINT0_Link"/>
    <child  link="LARM_JOINT1_Link"/>
    <origin xyz="0 0 0" rpy="0 -0 0 "/>
    <axis   xyz="0 1 0"/>
    <limit lower="-2.44346" upper="1.0472" effort="100" velocity="0.5" />
    <dynamics damping="0.4" friction="100.0" /> 
  </joint>
  
  <transmission name="LARM_JOINT1_TRANS">
    <type>transmission_interface/SimpleTransmission</type>
    <joint name="LARM_JOINT1">
      <hardwareInterface>EffortJointInterface</hardwareInterface>
    </joint>
    <actuator name="LARM_JOINT1_MOTOR">
      <hardwareInterface>EffortJointInterface</hardwareInterface>
      <mechanicalReduction>1</mechanicalReduction>
    </actuator>
  </transmission>
  
  <link name="LARM_JOINT2_Link">
    <visual>
      <origin xyz="0 0.095 -0.25" rpy="0 -0 0"/>
      <geometry>
        <mesh filename="package://hironx_description/meshes/LARM_JOINT2_Link_mesh.dae" scale="1 1 1" />
      </geometry>
    </visual>
    
    <collision>
      <origin xyz="0 0.095 -0.25" rpy="0 -0 0"/>
      <geometry>
        <mesh filename="package://hironx_description/meshes/LARM_JOINT2_Link_mesh.dae" scale="1 1 1" />
      </geometry>
    </collision>
    
    <inertial>
      <mass value="0.577518" />
      <origin xyz="-0.025 0.02167107 -0.0705116" rpy="0 -0 0"/>
      <inertia ixx="0.00113966" ixy="3e-07" ixz="1.2e-06" iyy="0.00111763" iyz="7.596e-05" izz="0.0004972"/>
      <!-- <origin xyz="-2.254e-05 0.00167107 -0.0715116" rpy="0 -0 0"/> -->
      <!-- <inertia ixx="0.00143966" ixy="-3e-07" ixz="1.2e-06" iyy="0.00141763" iyz="-7.596e-05" izz="0.0001972"/> -->
    </inertial>
  </link>
  
  <joint name="LARM_JOINT2" type="revolute">
    <parent link="LARM_JOINT1_Link"/>
    <child  link="LARM_JOINT2_Link"/>
    <origin xyz="0 0.095 -0.25" rpy="0 -0 0 "/>
    <axis   xyz="0 1 0"/>
    <limit lower="-2.75762" upper="0" effort="100" velocity="0.5" />
    <dynamics damping="0.4" friction="100.0" />
  </joint>
  
  <transmission name="LARM_JOINT2_TRANS">
    <type>transmission_interface/SimpleTransmission</type>
    <joint name="LARM_JOINT2">
      <hardwareInterface>EffortJointInterface</hardwareInterface>
    </joint>
    <actuator name="LARM_JOINT2_MOTOR">
      <hardwareInterface>EffortJointInterface</hardwareInterface>
      <mechanicalReduction>1</mechanicalReduction>
    </actuator>
  </transmission>
  
  <!-- <link name="LARM_JOINT3_Link">
    <visual>
      <origin xyz="-0.03 0 0" rpy="0 -0 0"/>
      <geometry>
        <mesh filename="package://hironx_description/meshes/LARM_JOINT3_Link_mesh.dae" scale="1 1 1" />
      </geometry>
    </visual>
    
    <collision>
      <origin xyz="-0.03 0 0" rpy="0 -0 0"/>
      <geometry>
        <mesh filename="package://hironx_description/meshes/LARM_JOINT3_Link_mesh.dae" scale="1 1 1" />
      </geometry>
    </collision>
    
    <inertial>
      <mass value="0.457418" /> -->
      <!-- <origin xyz="-1.788e-05 -0.00395812 -0.202731" rpy="0 -0 0"/> -->
      <!-- <origin xyz="-1.788e-05 0.00195812 -0.192731" rpy="0 -0 0"/>
      <inertia ixx="0.00039205" ixy="-3e-08" ixz="5.2e-07" iyy="0.00038903" iyz="1.915e-05" izz="0.00015509"/>  -->
      <!-- <inertia ixx="0.00069205" ixy="3e-08" ixz="5.2e-07" iyy="0.00068903" iyz="-1.915e-05" izz="0.00013509"/> -->
    <!-- </inertial>
  </link>
  
  <joint name="LARM_JOINT3" type="revolute">
    <parent link="LARM_JOINT2_Link"/>
    <child  link="LARM_JOINT3_Link"/>
    <origin xyz="-0.03 0 0" rpy="0 -0 0 "/>
    <axis   xyz="0 0 1"/>
    <limit lower="-2.87979" upper="1.8326" effort="100" velocity="0.5" /> 
    <dynamics damping="0.4" friction="100.0" />
  </joint>
  
  <transmission name="LARM_JOINT3_TRANS">
    <type>transmission_interface/SimpleTransmission</type>
    <joint name="LARM_JOINT3">
      <hardwareInterface>EffortJointInterface</hardwareInterface>
    </joint>
    <actuator name="LARM_JOINT3_MOTOR">
      <hardwareInterface>EffortJointInterface</hardwareInterface>
      <mechanicalReduction>1</mechanicalReduction>
    </actuator>
  </transmission>  -->
  
  <!-- <link name="LARM_JOINT4_Link">
    <visual>
      <origin xyz="0 0 -0.235" rpy="0 -0 0"/>
      <geometry>
        <mesh filename="package://hironx_description/meshes/LARM_JOINT4_Link_mesh.dae" scale="1 1 1" />
      </geometry>
    </visual>
    
    <collision>
      <origin xyz="0 0 -0.235" rpy="0 -0 0"/>
      <geometry>
        <mesh filename="package://hironx_description/meshes/LARM_JOINT4_Link_mesh.dae" scale="1 1 1" />
      </geometry>
    </collision>
    
    <inertial>
      <mass value="0.418434" /> -->
      <!-- <origin xyz="0.00243131 0.00379733 -0.0577036" rpy="0 -0 0"/> (original) -->
      <!-- <origin xyz="0.00243131 0.01579733 -0.0577036" rpy="0 -0 0"/>
      <inertia ixx="0.00052016" ixy="1.69e-06" ixz="7.9e-06" iyy="0.00050569" iyz="-5.377e-05" izz="0.00014004"/>
    </inertial>
  </link>
  
  <joint name="LARM_JOINT4" type="revolute">
    <parent link="LARM_JOINT3_Link"/>
    <child  link="LARM_JOINT4_Link"/>
    <origin xyz="0 0 -0.235" rpy="0 -0 0 "/>
    <axis   xyz="0 1 0"/>
    <limit lower="-1.74533" upper="1.74533" effort="100" velocity="0.5" /> -->
    <!-- <dynamics damping="0.0" friction="0.0" /> (original)-->
  <!-- </joint>
  
  <transmission name="LARM_JOINT4_TRANS">
    <type>transmission_interface/SimpleTransmission</type>
    <joint name="LARM_JOINT4">
      <hardwareInterface>EffortJointInterface</hardwareInterface>
    </joint>
    <actuator name="LARM_JOINT4_MOTOR">
      <hardwareInterface>EffortJointInterface</hardwareInterface>
      <mechanicalReduction>1</mechanicalReduction>
    </actuator>
  </transmission> -->
  
  <!-- <link name="LARM_JOINT5_Link">
    <visual>
      <origin xyz="-0.04 0 -0.09" rpy="0 -0 0"/>
      <geometry>
        <mesh filename="package://hironx_description/meshes/LARM_JOINT5_Link_mesh.dae" scale="1 1 1" />
      </geometry>
    </visual>
    
    <collision>
      <origin xyz="-0.04 0 -0.09" rpy="0 -0 0"/>
      <geometry>
        <mesh filename="package://hironx_description/meshes/LARM_JOINT5_Link_mesh.dae" scale="1 1 1" />
      </geometry>
    </collision>
    
    <inertial>
      <mass value="1.05156" />
      <origin xyz="-0.012 0 -0.015" rpy="0 -0 0"/> --> 
      <!-- <origin xyz="-0.048476 -3.2e-06 -0.0388988" rpy="0 -0 0"/> (original) -->
      <!-- <inertia ixx="0.00194072" ixy="1.1e-07" ixz="-0.00042482" iyy="0.00209392" iyz="1.2e-07" izz="0.00035788"/> (original) -->
      <!-- <inertia ixx="0.00169392" ixy="1.1e-07" ixz="-0.00042482" iyy="0.00026788" iyz="1.2e-07" izz="0.00174072"/>
    </inertial>
  </link>
  
  <joint name="LARM_JOINT5" type="revolute">
    <parent link="LARM_JOINT4_Link"/>
    <child  link="LARM_JOINT5_Link"/>
    <origin xyz="-0.04 0 -0.09" rpy="0 -0 0 "/>
    <axis   xyz="1 0 0"/> 
    <limit lower="-2.84489" upper="2.84489" effort="100" velocity="0.5" /> -->
    <!-- <dynamics damping="0.0" friction="0.0" /> -->
  <!-- </joint>
  
  <transmission name="LARM_JOINT5_TRANS">
    <type>transmission_interface/SimpleTransmission</type>
    <joint name="LARM_JOINT5">
      <hardwareInterface>EffortJointInterface</hardwareInterface>
    </joint>
    <actuator name="LARM_JOINT5_MOTOR">
      <hardwareInterface>EffortJointInterface</hardwareInterface>
      <mechanicalReduction>1</mechanicalReduction>
    </actuator>
  </transmission> -->
  
  <!-- <link name="LHAND_JOINT0_Link">
    <visual>
      <origin xyz="-0.0299 -0.033 0" rpy="0 -0 0"/>
      <geometry>
        <mesh filename="package://hironx_description/meshes/LHAND_JOINT0_Link_mesh.dae" scale="1 1 1" />
      </geometry>
    </visual>
    
    <collision>
      <origin xyz="-0.0299 -0.033 0" rpy="0 -0 0"/>
      <geometry>
        <mesh filename="package://hironx_description/meshes/LHAND_JOINT0_Link_mesh.dae" scale="1 1 1" />
      </geometry>
    </collision>
    
    <inertial>
	  <origin xyz="-0.0299 -0.001 0" rpy="0 -0 0"/>
      <mass value="0.01" /> -->
      <!-- <origin xyz="0 0 0" rpy="0 -0 0"/> -->
      <!-- <inertia ixx="0.000015926" ixy="0.000000044" ixz="-2.5144e-07" iyy="0.00008795" iyz="-1.3546e-08" izz="0.00090301"/>
    </inertial>
  </link> -->
  
  <!-- <joint name="LHAND_JOINT0" type="revolute">
    <parent link="LARM_JOINT5_Link"/>
    <child  link="LHAND_JOINT0_Link"/>
    <origin xyz="-0.0299 -0.033 0" rpy="0 -0 0 "/>
    <axis   xyz="0 0 1"/> 
    <limit lower="-0.523599" upper="0.523599" effort="100" velocity="0.5" /> -->
    <!-- <dynamics damping="0.0" friction="0.0" /> -->
  <!-- </joint>
  
  <transmission name="LHAND_JOINT0_TRANS">
    <type>transmission_interface/SimpleTransmission</type>
    <joint name="LHAND_JOINT0">
      <hardwareInterface>EffortJointInterface</hardwareInterface>
    </joint>
    <actuator name="LHAND_JOINT0_MOTOR">
      <hardwareInterface>EffortJointInterface</hardwareInterface>
      <mechanicalReduction>1</mechanicalReduction>
    </actuator>
  </transmission> -->
  
  <!-- <link name="LHAND_JOINT1_Link">
    <visual>
      <origin xyz="-0.0419 0 0" rpy="0 -0 0"/>
      <geometry>
        <mesh filename="package://hironx_description/meshes/LHAND_JOINT1_Link_mesh.dae" scale="1 1 1" />
      </geometry>
    </visual>
    
    <collision>
      <origin xyz="-0.0419 0 0" rpy="0 -0 0"/>
      <geometry>
        <mesh filename="package://hironx_description/meshes/LHAND_JOINT1_Link_mesh.dae" scale="1 1 1" />
      </geometry>
    </collision>
    
    <inertial>
	  <origin xyz="-0.019 0.01 0" rpy="0 -0 0"/>
      <mass value="0.01" />
      <inertia ixx="0.000015926" ixy="0.000000044" ixz="-2.5144e-07" iyy="0.00008795" iyz="-1.3546e-08" izz="0.00090301"/> -->
      <!-- <inertia ixx="0.05926" ixy="0.0044" ixz="-2.5144e-04" iyy="0.11795" iyz="-1.3546e-05" izz="0.10301"/> -->
    <!-- </inertial>
  </link> -->
  
  <!-- <joint name="LHAND_JOINT1" type="revolute">
    <parent link="LHAND_JOINT0_Link"/>
    <child  link="LHAND_JOINT1_Link"/>
    <origin xyz="-0.0419 0 0" rpy="0 -0 0 "/>
    <axis   xyz="0 0 1"/>
    <limit lower="-0.523599" upper="0.523599" effort="100" velocity="0.5" /> -->
    <!-- <dynamics damping="0.0" friction="0.0" /> -->
  <!-- </joint>
  
  <transmission name="LHAND_JOINT1_TRANS">
    <type>transmission_interface/SimpleTransmission</type>
    <joint name="LHAND_JOINT1">
      <hardwareInterface>EffortJointInterface</hardwareInterface>
    </joint>
    <actuator name="LHAND_JOINT1_MOTOR">
      <hardwareInterface>EffortJointInterface</hardwareInterface>
      <mechanicalReduction>1</mechanicalReduction>
    </actuator>
  </transmission> -->
  
  <!-- <link name="LHAND_JOINT2_Link">
    <visual>
      <origin xyz="-0.0299 0.033 0" rpy="0 -0 0"/>
      <geometry>
        <mesh filename="package://hironx_description/meshes/LHAND_JOINT2_Link_mesh.dae" scale="1 1 1" />
      </geometry>
    </visual>
    
    <collision>
      <origin xyz="-0.0299 0.033 0" rpy="0 -0 0"/>
      <geometry>
        <mesh filename="package://hironx_description/meshes/LHAND_JOINT2_Link_mesh.dae" scale="1 1 1" />
      </geometry>
    </collision> 
    
    <inertial>
	  <origin xyz="-0.0299 0.001 0" rpy="0 -0 0"/>
      <mass value="0.01" />
      <inertia ixx="0.000015926" ixy="0.000000044" ixz="-2.5144e-07" iyy="0.00008795" iyz="-1.3546e-08" izz="0.00090301"/>
    </inertial>
  </link>
  
  <joint name="LHAND_JOINT2" type="revolute">
    <parent link="LARM_JOINT5_Link"/>
    <child  link="LHAND_JOINT2_Link"/>
    <origin xyz="-0.0299 0.033 0" rpy="0 -0 0 "/>
    <axis   xyz="0 0 1"/>
    <limit lower="-0.523599" upper="0.523599" effort="100" velocity="0.5" /> -->
    <!-- <dynamics damping="0.0" friction="0.0" /> -->
  <!-- </joint>
  
  <transmission name="LHAND_JOINT2_TRANS">
    <type>transmission_interface/SimpleTransmission</type>
    <joint name="LHAND_JOINT2">
      <hardwareInterface>EffortJointInterface</hardwareInterface>
    </joint>
    <actuator name="LHAND_JOINT2_MOTOR">
      <hardwareInterface>EffortJointInterface</hardwareInterface>
      <mechanicalReduction>1</mechanicalReduction>
    </actuator>
  </transmission> -->
  
  <!-- <link name="LHAND_JOINT3_Link">
    <visual>
      <origin xyz="-0.0419 0 0" rpy="0 -0 0"/>
      <geometry>
        <mesh filename="package://hironx_description/meshes/LHAND_JOINT3_Link_mesh.dae" scale="1 1 1" />
      </geometry>
    </visual>
    
    <collision>
      <origin xyz="-0.0419 0 0" rpy="0 -0 0"/>
      <geometry>
        <mesh filename="package://hironx_description/meshes/LHAND_JOINT3_Link_mesh.dae" scale="1 1 1" />
      </geometry>
    </collision> 
    
    <inertial>
	  <origin xyz="-0.019 -0.01 0" rpy="0 -0 0"/>
      <mass value="0.01" />
      <inertia ixx="0.000015926" ixy="0.000000044" ixz="-2.5144e-07" iyy="0.00008795" iyz="-1.3546e-08" izz="0.00090301"/> -->
      <!-- <inertia ixx="0.05926" ixy="0.0044" ixz="-2.5144e-04" iyy="0.11795" iyz="-1.3546e-05" izz="0.10301"/> -->
    <!-- </inertial>
  </link>
  
  <joint name="LHAND_JOINT3" type="revolute">
    <parent link="LHAND_JOINT2_Link"/>
    <child  link="LHAND_JOINT3_Link"/>
    <origin xyz="-0.0419 0 0" rpy="0 -0 0 "/>
    <axis   xyz="0 0 1"/>
    <limit lower="-0.523599" upper="0.523599" effort="100" velocity="0.5" /> -->
    <!-- <dynamics damping="0.0" friction="0.0" /> -->
  <!-- </joint>
  
  <transmission name="LHAND_JOINT3_TRANS">
    <type>transmission_interface/SimpleTransmission</type>
    <joint name="LHAND_JOINT3">
      <hardwareInterface>EffortJointInterface</hardwareInterface>
    </joint>
    <actuator name="LHAND_JOINT3_MOTOR">
      <hardwareInterface>EffortJointInterface</hardwareInterface>
      <mechanicalReduction>1</mechanicalReduction>
    </actuator>
  </transmission> -->
  
  <link name="RARM_JOINT0_Link">
    <visual>
      <origin xyz="0 -0.145 0.370296" rpy="0.261799 -0 0"/>
      <geometry>
        <mesh filename="package://hironx_description/meshes/RARM_JOINT0_Link_mesh.dae" scale="1 1 1" />
      </geometry>
    </visual>
    
    <collision>
      <origin xyz="0 -0.145 0.370296" rpy="0.261799 -0 0"/>
      <geometry>
        <mesh filename="package://hironx_description/meshes/RARM_JOINT0_Link_mesh.dae" scale="1 1 1" />
      </geometry>
    </collision>
    
    <inertial>
      <mass value="1.32626" />
      <origin xyz="-0.00226388 -0.00521383 0.0176081" rpy="0 -0 0"/>
	  <inertia ixx="0.00207537" ixy="-0.00011276" ixz="8.927e-05" iyy="0.00240295" iyz="4.57e-05" izz="0.00141912"/> 
	  <!-- <origin xyz="-0.00226388 0.00521383 0.0156081" rpy="0 -0 0"/> -->
    </inertial>
  </link>
  
  <joint name="RARM_JOINT0" type="revolute">
    <parent link="CHEST_JOINT0_Link"/>
    <child  link="RARM_JOINT0_Link"/>
    <origin xyz="0 -0.145 0.370296" rpy="0.261799 -0 0 "/>
    <axis   xyz="0 0 1"/>
    <limit lower="-1.53589" upper="1.53589" effort="100" velocity="0.5" /> 
    <dynamics damping="0.4" friction="100.0" />
  </joint>
  
  <transmission name="RARM_JOINT0_TRANS">
    <type>transmission_interface/SimpleTransmission</type>
    <joint name="RARM_JOINT0">
      <hardwareInterface>EffortJointInterface</hardwareInterface>
    </joint>
    <actuator name="RARM_JOINT0_MOTOR">
      <hardwareInterface>EffortJointInterface</hardwareInterface>
      <mechanicalReduction>1</mechanicalReduction>
    </actuator>
  </transmission> 
  
  <link name="RARM_JOINT1_Link">
    <visual>
      <origin xyz="0 0 0" rpy="0 -0 0"/>
      <geometry>
        <mesh filename="package://hironx_description/meshes/RARM_JOINT1_Link_mesh.dae" scale="1 1 1" />
      </geometry>
    </visual>
    
    <collision>
      <origin xyz="0 0 0" rpy="0 -0 0"/>
      <geometry>
        <mesh filename="package://hironx_description/meshes/RARM_JOINT1_Link_mesh.dae" scale="1 1 1" />
      </geometry>
    </collision>
    
    <inertial>
      <mass value="1.14898" />
      <origin xyz="-0.025 -0.1083134 -0.127061" rpy="0 -0 0"/>
      <inertia ixx="0.0124168" ixy="-9.95417e-07" ixz="3.38147e-06" iyy="0.0127117" iyz="-0.00213719" izz="0.0013658"/>
      <!-- <origin xyz="-5.236e-05 -0.0583134 -0.107061" rpy="0 -0 0"/> -->
      <!-- <inertia ixx="0.0154168" ixy="-9.95417e-07" ixz="3.38147e-06" iyy="0.0147117" iyz="-0.00213719" izz="0.0012658"/> -->
    </inertial>
  </link>
  
  <joint name="RARM_JOINT1" type="revolute">
    <parent link="RARM_JOINT0_Link"/>
    <child  link="RARM_JOINT1_Link"/>
    <origin xyz="0 0 0" rpy="0 -0 0 "/>
    <axis   xyz="0 1 0"/>
    <limit lower="-2.44346" upper="1.0472" effort="100" velocity="0.5" /> -->
    <dynamics damping="0.4" friction="100.0" /> 
  </joint>
  
  <transmission name="RARM_JOINT1_TRANS">
    <type>transmission_interface/SimpleTransmission</type>
    <joint name="RARM_JOINT1">
      <hardwareInterface>EffortJointInterface</hardwareInterface>
    </joint>
    <actuator name="RARM_JOINT1_MOTOR">
      <hardwareInterface>EffortJointInterface</hardwareInterface>
      <mechanicalReduction>1</mechanicalReduction>
    </actuator>
  </transmission>
  
  <link name="RARM_JOINT2_Link">
    <visual>
      <origin xyz="0 -0.095 -0.25" rpy="0 -0 0"/>
      <geometry>
        <mesh filename="package://hironx_description/meshes/RARM_JOINT2_Link_mesh.dae" scale="1 1 1" />
      </geometry>
    </visual>
    
    <collision>
      <origin xyz="0 -0.095 -0.25" rpy="0 -0 0"/>
      <geometry>
        <mesh filename="package://hironx_description/meshes/RARM_JOINT2_Link_mesh.dae" scale="1 1 1" />
      </geometry>
    </collision>
    
    <inertial>
      <mass value="0.577518" />
      <origin xyz="-0.025 -0.02167107 -0.0705116" rpy="0 -0 0"/>
      <inertia ixx="0.00113966" ixy="3e-07" ixz="1.2e-06" iyy="0.00111763" iyz="7.596e-05" izz="0.0004972"/> 
      <!-- <origin xyz="-2.254e-05 -0.00167107 -0.0715116" rpy="0 -0 0"/> -->
      <!-- <inertia ixx="0.00143966" ixy="3e-07" ixz="1.2e-06" iyy="0.00141763" iyz="7.596e-05" izz="0.0001972"/> -->
    </inertial>
  </link>
  
  <joint name="RARM_JOINT2" type="revolute">
    <parent link="RARM_JOINT1_Link"/>
    <child  link="RARM_JOINT2_Link"/>
    <origin xyz="0 -0.095 -0.25" rpy="0 -0 0 "/>
    <axis   xyz="0 1 0"/>
    <limit lower="-2.75762" upper="0" effort="100" velocity="0.5" /> 
    <dynamics damping="0.4" friction="100.0" />
  </joint>
  
  <transmission name="RARM_JOINT2_TRANS">
    <type>transmission_interface/SimpleTransmission</type>
    <joint name="RARM_JOINT2">
      <hardwareInterface>EffortJointInterface</hardwareInterface>
    </joint>
    <actuator name="RARM_JOINT2_MOTOR">
      <hardwareInterface>EffortJointInterface</hardwareInterface>
      <mechanicalReduction>1</mechanicalReduction>
    </actuator>
  </transmission>
  
  <!-- <link name="RARM_JOINT3_Link">
    <visual>
      <origin xyz="-0.03 0 0" rpy="0 -0 0"/>
      <geometry>
        <mesh filename="package://hironx_description/meshes/RARM_JOINT3_Link_mesh.dae" scale="1 1 1" />
      </geometry>
    </visual>
    
    <collision>
      <origin xyz="-0.03 0 0" rpy="0 -0 0"/>
      <geometry>
        <mesh filename="package://hironx_description/meshes/RARM_JOINT3_Link_mesh.dae" scale="1 1 1" />
      </geometry>
    </collision>
    
    <inertial> -->
      <!-- <mass value="0.457418" /> -->
      <!-- <mass value="2.17418" />
      <origin xyz="-1.788e-05 -0.00195812 -0.192731" rpy="0 -0 0"/>
      <inertia ixx="0.00039205" ixy="-3e-08" ixz="5.2e-07" iyy="0.00038903" iyz="1.915e-05" izz="0.00015509"/> -->
      <!-- <origin xyz="-1.788e-05 0.00395812 -0.202731" rpy="0 -0 0"/> -->
      <!-- <inertia ixx="0.00069205" ixy="-3e-08" ixz="5.2e-07" iyy="0.00068903" iyz="1.915e-05" izz="0.00013509"/> -->
    <!-- </inertial>
  </link> -->
  
  <!-- <joint name="RARM_JOINT3" type="revolute">
    <parent link="RARM_JOINT2_Link"/>
    <child  link="RARM_JOINT3_Link"/>
    <origin xyz="-0.03 0 0" rpy="0 -0 0 "/>
    <axis   xyz="0 0 1"/>
    <limit lower="-2.87979" upper="1.8326" effort="100" velocity="0.5" />
    <dynamics damping="0.4" friction="100.0" />
  </joint>
  
  <transmission name="RARM_JOINT3_TRANS">
    <type>transmission_interface/SimpleTransmission</type>
    <joint name="RARM_JOINT3">
      <hardwareInterface>EffortJointInterface</hardwareInterface>
    </joint>
    <actuator name="RARM_JOINT3_MOTOR">
      <hardwareInterface>EffortJointInterface</hardwareInterface>
      <mechanicalReduction>1</mechanicalReduction>
    </actuator>
  </transmission> -->
  
  <!-- <link name="RARM_JOINT4_Link">
    <visual>
      <origin xyz="0 0 -0.235" rpy="0 -0 0"/>
      <geometry>
        <mesh filename="package://hironx_description/meshes/RARM_JOINT4_Link_mesh.dae" scale="1 1 1" />
      </geometry>
    </visual>
    
    <collision>
      <origin xyz="0 0 -0.235" rpy="0 -0 0"/>
      <geometry>
        <mesh filename="package://hironx_description/meshes/RARM_JOINT4_Link_mesh.dae" scale="1 1 1" />
      </geometry>
    </collision>
    
    <inertial>
      <mass value="0.418434" />
      <origin xyz="0.00243131 -0.01579733 -0.0577036" rpy="0 -0 0"/>
      <inertia ixx="0.00052016" ixy="-1.69e-06" ixz="7.9e-06" iyy="0.00050569" iyz="5.377e-05" izz="0.00014004"/> -->
      <!-- <origin xyz="0.00243131 -0.00379733 -0.0577036" rpy="0 -0 0"/> -->
    <!-- </inertial>
  </link>
  
  <joint name="RARM_JOINT4" type="revolute">
    <parent link="RARM_JOINT3_Link"/>
    <child  link="RARM_JOINT4_Link"/>
    <origin xyz="0 0 -0.235" rpy="0 -0 0 "/>
    <axis   xyz="0 1 0"/>
    <limit lower="-1.74533" upper="1.74533" effort="100" velocity="0.5" /> -->
    <!-- <dynamics damping="0.0" friction="0.0" /> -->
  <!-- </joint>
  
  <transmission name="RARM_JOINT4_TRANS">
    <type>transmission_interface/SimpleTransmission</type>
    <joint name="RARM_JOINT4">
      <hardwareInterface>EffortJointInterface</hardwareInterface>
    </joint>
    <actuator name="RARM_JOINT4_MOTOR">
      <hardwareInterface>EffortJointInterface</hardwareInterface>
      <mechanicalReduction>1</mechanicalReduction>
    </actuator>
  </transmission> -->
  
  <!-- <link name="RARM_JOINT5_Link">
    <visual>
      <origin xyz="-0.04 0 -0.09" rpy="0 -0 0"/>
      <geometry>
        <mesh filename="package://hironx_description/meshes/RARM_JOINT5_Link_mesh.dae" scale="1 1 1" />
      </geometry>
    </visual>
    
    <collision>
      <origin xyz="-0.04 0 -0.09" rpy="0 -0 0"/>
      <geometry>
        <mesh filename="package://hironx_description/meshes/RARM_JOINT5_Link_mesh.dae" scale="1 1 1" />
      </geometry>
    </collision>
    
    <inertial>
      <mass value="1.05156" /> -->
      <!-- <origin xyz="-0.048476 3.2e-06 -0.0388988" rpy="0 -0 0"/> (original) --> 
      <!-- <origin xyz="-0.012 0 -0.015" rpy="0 -0 0"/>
      <inertia ixx="0.00169392" ixy="1.1e-07" ixz="-0.00042482" iyy="0.00026788" iyz="1.2e-07" izz="0.00174072"/> -->
      <!-- <inertia ixx="0.00194072" ixy="-1.1e-07" ixz="-0.00042482" iyy="0.00209392" iyz="-1.2e-07" izz="0.00035788"/> (original) -->
    <!-- </inertial>
  </link>
  
  <joint name="RARM_JOINT5" type="revolute">
    <parent link="RARM_JOINT4_Link"/>
    <child  link="RARM_JOINT5_Link"/>
    <origin xyz="-0.04 0 -0.09" rpy="0 -0 0 "/>
    <axis   xyz="1 0 0"/>
    <limit lower="-2.84489" upper="2.84489" effort="100" velocity="0.5" /> -->
    <!-- <dynamics damping="0.0" friction="0.0" /> -->
  <!-- </joint>
  
  <transmission name="RARM_JOINT5_TRANS">
    <type>transmission_interface/SimpleTransmission</type>
    <joint name="RARM_JOINT5">
      <hardwareInterface>EffortJointInterface</hardwareInterface>
    </joint>
    <actuator name="RARM_JOINT5_MOTOR">
      <hardwareInterface>EffortJointInterface</hardwareInterface>
      <mechanicalReduction>1</mechanicalReduction>
    </actuator>
  </transmission> -->
  
  <!-- <link name="RHAND_JOINT0_Link">
    <visual>
      <origin xyz="-0.0299 -0.033 0" rpy="0 -0 0"/>
      <geometry>
        <mesh filename="package://hironx_description/meshes/RHAND_JOINT0_Link_mesh.dae" scale="1 1 1" />
      </geometry>
    </visual>
    
    <collision>
      <origin xyz="-0.0299 -0.033 0" rpy="0 -0 0"/>
      <geometry>
        <mesh filename="package://hironx_description/meshes/RHAND_JOINT0_Link_mesh.dae" scale="1 1 1" />
      </geometry>
    </collision>
    
    <inertial>
      <origin xyz="-0.0299 -0.001 0" rpy="0 -0 0"/>
      <mass value="0.01" />
      <inertia ixx="0.000015926" ixy="0.000000044" ixz="-2.5144e-07" iyy="0.00008795" iyz="-1.3546e-08" izz="0.00090301"/>
    </inertial>
  </link>
  
  <joint name="RHAND_JOINT0" type="revolute">
    <parent link="RARM_JOINT5_Link"/>
    <child  link="RHAND_JOINT0_Link"/>
    <origin xyz="-0.0299 -0.033 0" rpy="0 -0 0 "/>
    <axis   xyz="0 0 1"/>
    <limit lower="-0.523599" upper="0.523599" effort="100" velocity="0.5" /> -->
    <!-- <dynamics damping="0.0" friction="0.0" /> -->
  <!-- </joint>
  
  <transmission name="RHAND_JOINT0_TRANS">
    <type>transmission_interface/SimpleTransmission</type>
    <joint name="RHAND_JOINT0">
      <hardwareInterface>EffortJointInterface</hardwareInterface>
    </joint>
    <actuator name="RHAND_JOINT0_MOTOR">
      <hardwareInterface>EffortJointInterface</hardwareInterface>
      <mechanicalReduction>1</mechanicalReduction>
    </actuator>
  </transmission> -->
  
  <!-- <link name="RHAND_JOINT1_Link">
    <visual>
      <origin xyz="-0.0419 0 0" rpy="0 -0 0"/>
      <geometry>
        <mesh filename="package://hironx_description/meshes/RHAND_JOINT1_Link_mesh.dae" scale="1 1 1" />
      </geometry>
    </visual>
    
    <collision>
      <origin xyz="-0.0419 0 0" rpy="0 -0 0"/>
      <geometry>
        <mesh filename="package://hironx_description/meshes/RHAND_JOINT1_Link_mesh.dae" scale="1 1 1" />
      </geometry>
    </collision>
    
    <inertial>
      <origin xyz="-0.019 0.01 0" rpy="0 -0 0"/>
      <mass value="0.01" />
      <inertia ixx="0.000015926" ixy="0.000000044" ixz="-2.5144e-07" iyy="0.00008795" iyz="-1.3546e-08" izz="0.00090301"/>
    </inertial>
  </link> -->
  
  <!-- <joint name="RHAND_JOINT1" type="revolute">
    <parent link="RHAND_JOINT0_Link"/>
    <child  link="RHAND_JOINT1_Link"/>
    <origin xyz="-0.0419 0 0" rpy="0 -0 0 "/>
    <axis   xyz="0 0 1"/> 
    <limit lower="-0.523599" upper="0.523599" effort="100" velocity="0.5" /> -->
    <!-- <dynamics damping="0.0" friction="0.0" /> -->
  <!-- </joint> 
  
  <transmission name="RHAND_JOINT1_TRANS">
    <type>transmission_interface/SimpleTransmission</type>
    <joint name="RHAND_JOINT1">
      <hardwareInterface>EffortJointInterface</hardwareInterface>
    </joint>
    <actuator name="RHAND_JOINT1_MOTOR">
      <hardwareInterface>EffortJointInterface</hardwareInterface>
      <mechanicalReduction>1</mechanicalReduction>
    </actuator>
  </transmission> -->
  
  <!-- <link name="RHAND_JOINT2_Link">
    <visual>
      <origin xyz="-0.0299 0.033 0" rpy="0 -0 0"/>
      <geometry>
        <mesh filename="package://hironx_description/meshes/RHAND_JOINT2_Link_mesh.dae" scale="1 1 1" />
      </geometry>
    </visual>
    
    <collision>
      <origin xyz="-0.0299 0.033 0" rpy="0 -0 0"/>
      <geometry>
        <mesh filename="package://hironx_description/meshes/RHAND_JOINT2_Link_mesh.dae" scale="1 1 1" />
      </geometry>
    </collision>
    
    <inertial>
      <origin xyz="-0.0299 0.001 0" rpy="0 -0 0"/>
      <mass value="0.01" />
      <inertia ixx="0.000015926" ixy="0.000000044" ixz="-2.5144e-07" iyy="0.00008795" iyz="-1.3546e-08" izz="0.00090301"/>
    </inertial>
  </link>
  
  <joint name="RHAND_JOINT2" type="revolute">
    <parent link="RARM_JOINT5_Link"/>
    <child  link="RHAND_JOINT2_Link"/>
    <origin xyz="-0.0299 0.033 0" rpy="0 -0 0 "/>
    <axis   xyz="0 0 1"/>
    <limit lower="-0.523599" upper="0.523599" effort="100" velocity="0.5" /> -->
    <!-- <dynamics damping="0.0" friction="0.0" /> -->
  <!-- </joint>
  
  <transmission name="RHAND_JOINT2_TRANS">
    <type>transmission_interface/SimpleTransmission</type>
    <joint name="RHAND_JOINT2">
      <hardwareInterface>EffortJointInterface</hardwareInterface>
    </joint>
    <actuator name="RHAND_JOINT2_MOTOR">
      <hardwareInterface>EffortJointInterface</hardwareInterface>
      <mechanicalReduction>1</mechanicalReduction>
    </actuator>
  </transmission> -->
  
  <!-- <link name="RHAND_JOINT3_Link">
    <visual>
      <origin xyz="-0.0419 0 0" rpy="0 -0 0"/>
      <geometry>
        <mesh filename="package://hironx_description/meshes/RHAND_JOINT3_Link_mesh.dae" scale="1 1 1" />
      </geometry>
    </visual>
    
    <collision>
      <origin xyz="-0.0419 0 0" rpy="0 -0 0"/>
      <geometry>
        <mesh filename="package://hironx_description/meshes/RHAND_JOINT3_Link_mesh.dae" scale="1 1 1" />
      </geometry>
    </collision>
    
    <inertial>
      <origin xyz="-0.019 -0.01 0" rpy="0 -0 0"/>
      <mass value="0.01" />
      <inertia ixx="0.000015926" ixy="0.000000044" ixz="-2.5144e-07" iyy="0.00008795" iyz="-1.3546e-08" izz="0.00090301"/>
    </inertial>
  </link> -->
  
  <!-- <joint name="RHAND_JOINT3" type="revolute">
    <parent link="RHAND_JOINT2_Link"/>
    <child  link="RHAND_JOINT3_Link"/>
    <origin xyz="-0.0419 0 0" rpy="0 -0 0 "/>
    <axis   xyz="0 0 1"/>
    <limit lower="-0.523599" upper="0.523599" effort="100" velocity="0.5" /> -->
    <!-- <dynamics damping="0.0" friction="0.0" /> -->
  <!-- </joint>
  
  <transmission name="RHAND_JOINT3_TRANS">
    <type>transmission_interface/SimpleTransmission</type>
    <joint name="RHAND_JOINT3">
      <hardwareInterface>EffortJointInterface</hardwareInterface>
    </joint>
    <actuator name="RHAND_JOINT3_MOTOR">
      <hardwareInterface>EffortJointInterface</hardwareInterface>
      <mechanicalReduction>1</mechanicalReduction>
    </actuator>
  </transmission> -->

</robot>
